<?xml version="1.0"?>
<robot xmlns:xacro="https://www.ros.org/wiki/xacro" name="bastion" version="1.0">

    <!-- TODO: Write comments for sections and each link and joint -->

    <link name="base_link">
        <collision name="base_collision">
            <origin rpy="0.00000 0.00000 -0.07693" xyz="-0.00000 -0.00000 -0.01116"/>
            <geometry>
                <mesh filename="package://bastion_description/models/bastion_v1/meshes/collisions/base.stl" scale="1.00000 1.00000 1.00000"/>
            </geometry>
        </collision>
        <inertial>
            <inertia ixx="0.00033" ixy="0.00001" ixz="-0.00002" iyy="0.00045" iyz="0.00000" izz="0.00049"/>
            <origin rpy="0.00000 0.00000 0.00000" xyz="-0.00000 -0.00001 -0.01117"/>
            <mass value="0.30000"/>
        </inertial>
        <visual name="base">
            <origin rpy="0.00000 0.00000 -0.00000" xyz="-0.00000 -0.00000 -0.01045"/>

            <geometry>
                <mesh filename="package://bastion_description/models/bastion_v1/meshes/visuals/base.dae" scale="1.00000 1.00000 1.00000"/>
            </geometry>
        </visual>
    </link>

    <link name="head_link">
        <collision name="head_collision">
            <origin rpy="0.00000 0.00000 -0.00085" xyz="-0.00000 -0.00000 0.00000"/>
            <geometry>
                <mesh filename="package://bastion_description/models/bastion_v1/meshes/collisions/head.stl" scale="1.00000 1.00000 1.00000"/>
            </geometry>
        </collision>
        <inertial>
            <inertia ixx="0.00004" ixy="0.00000" ixz="-0.00001" iyy="0.00007" iyz="0.00000" izz="0.00005"/>
            <origin rpy="0.00000 0.00000 0.00000" xyz="0.00539 -0.00030 0.02003"/>
            <mass value="0.10000"/>
        </inertial>
        <visual name="head">
            <origin rpy="0.00000 0.00000 0.00000" xyz="-0.00000 -0.00000 0.00000"/>

            <geometry>
                <mesh filename="package://bastion_description/models/bastion_v1/meshes/visuals/head.dae" scale="1.00000 1.00000 1.00000"/>
            </geometry>
        </visual>
    </link>

    <link name="left_arm_link">
        <collision name="left_arm_collision">
            <origin rpy="1.55502 -0.22218 -0.28790" xyz="-0.00000 0.00000 0.00000"/>
            <geometry>
                <mesh filename="package://bastion_description/models/bastion_v1/meshes/collisions/left_arm.stl" scale="1.00000 1.00000 1.00000"/>
            </geometry>
        </collision>
        <inertial>
            <inertia ixx="0.00314" ixy="0.00009" ixz="-0.00109" iyy="0.00351" iyz="0.00030" izz="0.00062"/>
            <origin rpy="0.00000 0.00000 0.00000" xyz="-0.01016 0.02891 0.05804"/>
            <mass value="0.30000"/>
        </inertial>
        <visual name="left_arm">
            <origin rpy="1.57035 -0.23737 -0.27914" xyz="-0.00000 0.00000 0.00000"/>

            <geometry>
                <mesh filename="package://bastion_description/models/bastion_v1/meshes/visuals/left_arm.dae" scale="1.00000 1.00000 1.00000"/>
            </geometry>
        </visual>
    </link>

    <link name="left_leg_link">
        <collision name="left_leg_collision">
            <origin rpy="1.55589 -0.07879 -0.17754" xyz="0.00124 -0.00591 0.00049"/>
            <geometry>
                <mesh filename="package://bastion_description/models/bastion_v1/meshes/collisions/left_leg.stl" scale="1.00000 1.00000 1.00000"/>
            </geometry>
        </collision>
        <inertial>
            <inertia ixx="0.00110" ixy="0.00001" ixz="-0.00004" iyy="0.00118" iyz="0.00007" izz="0.00022"/>
            <origin rpy="0.00000 0.00000 0.00000" xyz="-0.02113 0.06956 0.01913"/>
            <mass value="0.30000"/>
        </inertial>
        <visual name="left_leg">
            <origin rpy="1.57622 -0.09060 -0.21502" xyz="0.00124 -0.00591 0.00049"/>

            <geometry>
                <mesh filename="package://bastion_description/models/bastion_v1/meshes/visuals/left_leg.dae" scale="1.00000 1.00000 1.00000"/>
            </geometry>
        </visual>
    </link>

    <link name="right_arm_link">
        <collision name="right_arm_collision.000.001">
            <origin rpy="-1.54602 -0.27879 0.93631" xyz="-0.00000 -0.00000 -0.00000"/>
            <geometry>
                <mesh filename="package://bastion_description/models/bastion_v1/meshes/collisions/right_arm.stl" scale="1.00000 1.00000 1.00000"/>
            </geometry>
        </collision>
        <inertial>
            <inertia ixx="0.00336" ixy="-0.00002" ixz="-0.00077" iyy="0.00353" iyz="-0.00014" izz="0.00038"/>
            <origin rpy="0.00000 0.00000 0.00000" xyz="0.00934 -0.03194 0.05657"/>
            <mass value="0.30000"/>
        </inertial>
        <visual name="right_arm">
            <origin rpy="-1.49756 -0.20450 0.89827" xyz="-0.00000 -0.00000 0.00000"/>

            <geometry>
                <mesh filename="package://bastion_description/models/bastion_v1/meshes/visuals/right_arm.dae" scale="1.00000 1.00000 1.00000"/>
            </geometry>
        </visual>

    </link>

    <link name="right_leg_link">
        <collision name="right leg_collision">
            <origin rpy="-1.64482 -0.10708 0.19494" xyz="0.00042 0.00026 -0.00554"/>
            <geometry>
                <mesh filename="package://bastion_description/models/bastion_v1/meshes/collisions/right_leg.stl" scale="1.00000 1.00000 1.00000"/>
            </geometry>
        </collision>
        <inertial>
            <inertia ixx="0.00110" ixy="-0.00001" ixz="-0.00005" iyy="0.00116" iyz="-0.00015" izz="0.00024"/>
            <origin rpy="0.00000 0.00000 0.00000" xyz="-0.02220 -0.07367 0.01821"/>
            <mass value="0.30000"/>
        </inertial>
        <visual name="right leg">
            <origin rpy="-1.57746 -0.07125 0.20445" xyz="0.00080 0.00010 -0.00875"/>

            <geometry>
                <mesh filename="package://bastion_description/models/bastion_v1/meshes/visuals/right_leg.dae" scale="1.00000 1.00000 1.00000"/>
            </geometry>
        </visual>
    </link>

    <link name="waist_link">
        <collision name="waist_collision">
            <origin rpy="0.00000 0.00000 0.00000" xyz="0.00000 0.00000 0.00000"/>
            <geometry>
                <mesh filename="package://bastion_description/models/bastion_v1/meshes/collisions/waist.stl" scale="1.00000 1.00000 1.00000"/>
            </geometry>
        </collision>
        <inertial>
            <inertia ixx="0.00013" ixy="0.00000" ixz="-0.00003" iyy="0.00017" iyz="0.00000" izz="0.00017"/>
            <origin rpy="0.00000 0.00000 0.00000" xyz="-0.00090 -0.00101 -0.02636"/>
            <mass value="0.20000"/>
        </inertial>
        <visual name="waist">
            <origin rpy="0.00000 0.00000 0.13859" xyz="0.00000 0.00000 0.00000"/>

            <geometry>
                <mesh filename="package://bastion_description/models/bastion_v1/meshes/visuals/waist.dae" scale="1.00000 1.00000 1.00000"/>
            </geometry>
        </visual>
    </link>

    <joint name="head_link_joint" type="revolute">
        <limit lower="-1.57000" upper="1.57000" effort="0.00000" velocity="0.00000"/>
        <origin rpy="0.00000 0.00000 -0.01023" xyz="0.01007 0.00197 0.03947"/>
        <parent link="base_link"/>
        <child link="head_link"/>
        <axis xyz="0.00000 0.00000 1.00000"/>
    </joint>

    <joint name="left_arm_link_joint" type="revolute">
        <limit lower="-1.57000" upper="1.57000" effort="0.00000" velocity="0.00000"/>
        <origin rpy="-1.53929 0.10637 -0.23127" xyz="0.03229 0.06031 -0.00517"/>
        <parent link="base_link"/>
        <child link="left_arm_link"/>
        <axis xyz="0.00000 0.00000 1.00000"/>
    </joint>

    <joint name="left_leg_link_joint" type="revolute">
        <limit lower="-3.14000" upper="3.14000" effort="0.00000" velocity="0.00000"/>
        <origin rpy="-1.57001 0.14661 -0.13414" xyz="-0.00902 0.04323 -0.04967"/>
        <parent link="waist_link"/>
        <child link="left_leg_link"/>
        <axis xyz="0.00000 0.00000 1.00000"/>
    </joint>

    <joint name="right_arm_link_joint" type="revolute">
        <limit lower="-1.57000" upper="1.57000" effort="0.00000" velocity="0.00000"/>
        <origin rpy="1.52711 0.81496 0.14808" xyz="0.03137 -0.06034 -0.01017"/>
        <parent link="base_link"/>
        <child link="right_arm_link"/>
        <axis xyz="0.00000 0.00000 -1.00000"/>
    </joint>

    <joint name="right_leg_link_joint" type="revolute">
        <limit lower="-3.14000" upper="3.14000" effort="0.00000" velocity="0.00000"/>
        <origin rpy="1.56485 0.13082 -0.03626" xyz="0.00533 -0.05577 -0.04575"/>
        <parent link="waist_link"/>
        <child link="right_leg_link"/>
        <axis xyz="0.00000 0.00000 -1.00000"/>
    </joint>

    <joint name="waist_link_joint" type="revolute">
        <limit lower="-0.26200" upper="0.26000" effort="0.00000" velocity="0.00000"/>
        <origin rpy="-0.00199 0.00947 -0.00125" xyz="0.00492 0.00604 -0.06456"/>
        <parent link="base_link"/>
        <child link="waist_link"/>
        <axis xyz="0.00000 0.00000 1.00000"/>
    </joint>



</robot>